Workbook

Sheet 기초진단
D2: 일시 | E2: 44906 | AB2: 하나만 선택하세요
D3: 기업명 | E3: 협동조합 가나다
D4: 작성자 | E4: 강호동 대표
A6: 단계 | B6: 연번 | C6: 질문 | P6: 점수체계 | Q6: 해당점수 | R6: 코멘트 | T6: 하나만 선택하세요
A7: 사업경험 | B7: 확인 | C7: 과거에 사업경험이 있다 | D7: =IF(COUNTIF(F7:H7,TRUE)=0,"체크해주세요",IF(COUNTIF(F7:H7,TRUE)>1,"하나만 선택하세요","")) | E7: 있다 | F7: TRUE | G7: 없다 | H7: FALSE | T7: =IF(AND(F7=TRUE,F8=TRUE),"사업경험도 있고 동종업종 경험도 있음을",IF(AND(F7=TRUE,F8=FALSE),"사업경험도 있음을",IF(AND(F7=FALSE,F8=TRUE),"사업경험은 없으나 동종업종 경험이 있음을","사업경험이나 동종업종 경험이 없음을"))) -> 사업경험도 있고 동종업종 경험도 있음을
A8: 업종경험 | B8: 확인 | C8: 해당 업계에 종사한 경험이 있다 | D8: =IF(COUNTIF(F8:H8,TRUE)=0,"체크해주세요",IF(COUNTIF(F8:H8,TRUE)>1,"하나만 선택하세요","")) | E8: 있다 | F8: TRUE | G8: 없다 | H8: FALSE
A9: 1단계 | B9: 1 | C9: 해결하고자 하는 사회적문제에 대한 해결방안 계획에 대한 질문입니다 | E9: =IF(COUNTIF(F10:F13,TRUE)=0,"체크해주세요",IF(COUNTIF(F10:F13,TRUE)>1,"하나만 선택하세요","")) | P9: 1 | Q9: =SUM(Q10:Q13) -> 4 | T9: 관점 | U9: 범주 | V9: 요인 | W9: 하위요인 | X9: 단계 | Y9: 해당점수 | Z9: 범주점수 | AA9: 관점점수 | AB9: No | AC9: 코멘트
C10: ㄴ 1. 해결하고자 하는 사회적 문제가 있지만 아직 명확하지 않다 | F10: FALSE | P10: 0.5 | Q10: =IF(F10=TRUE,P10,0) -> 0 | R10: 해결하고자 하는 사회적문제를 명확히 정의하고 | T10: 확인 | V10: 사업경험 | W10: 사업경험 | X10: 사업경험 | AC10: =IF(AND(F7=TRUE,F8=TRUE),"사업경험도 있고 동종업종 경험도 있음을",IF(AND(F7=TRUE,F8=FALSE),"사업경험도 있음을",IF(AND(F7=FALSE,F8=TRUE),"사업경험은 없으나 동종업종 경험이 있음을","사업경험이나 동종업종 경험이 없음을"))) -> 사업경험도 있고 동종업종 경험도 있음을
C11: ㄴ 2. 해결하고자 하는 사회적 문제가 분명하지만 아직 구체적인 해결 계획은 없다 | F11: FALSE | P11: 1 | Q11: =IF(F11=TRUE,P11,0) -> 0 | R11: 사회적문제 해결을 위한 구체적인 해결 계획을 수립하고 | V11: 동종업종경험 | W11: 동종업종경험 | X11: 동업종경험
C12: ㄴ 3. 해결하고자 하는 사회적 문제가 분명하고 구체적인 해결 계획을 가지고 있다 | F12: TRUE | P12: 4 | Q12: =IF(F12=TRUE,P12,0) -> 4 | R12: 사회적문제 해결을 위한 계획과 목표달성을 위한 세부전략을 마련하고 | T12: 사회적성과 | U12: 조직미션 | V12: 소셜미션 | W12: 소셜미션 | X12: 1단계 | Y12: =Q9 -> 4 | Z12: =AVERAGE(Y12:Y15) -> 4.5 | AA12: =AVERAGE(Z12:Z27) -> 3.2777778 | AB12: 1 | AC12: =VLOOKUP(Y12,Q10:R13,2,0) -> 사회적문제 해결을 위한 계획과 목표달성을 위한 세부전략을 마련하고
C13: ㄴ 4. 해결하고자 하는 사회적 문제가 분명하고 계획이 구체적이며, 이에 따른 여러가지 시도를 해봤다 | F13: FALSE | P13: 5 | Q13: =IF(F13=TRUE,P13,0) -> 0 | R13: 사회적문제 해결을 위한 시도의 결과를 분석하며 개선점을 도출하고 | W13: 소셜미션실천 | X13: 2단계
A14: 1단계 | B14: 2 | C14: 사업계획에 대한 질문입니다 | E14: =IF(COUNTIF(F15:F18,TRUE)=0,"체크해주세요",IF(COUNTIF(F15:F18,TRUE)>1,"하나만 선택하세요","")) | P14: 2 | Q14: =SUM(Q15:Q18) -> 5 | V14: 성과관리체계 | W14: 사업계획수립 | X14: 1단계 | Y14: =Q14 -> 5 | AB14: 2 | AC14: =VLOOKUP(Y14,Q15:R18,2,0) -> 사업성과를 정기적으로 평가하며 피드백을 통해 계획을 보완하여야함
C15: ㄴ 1. 연초에 사업계획을 세운다 | F15: FALSE | P15: 0.5 | Q15: =IF(F15=TRUE,P15,0) -> 0 | R15: 사업계획 목표와 전략을 명확히 문서화하여 공유해야할 필요있음 | W15: 성과관리 (중간점검 및 결과분석) | X15: 2단계
C16: ㄴ 2. 연초에 사업계획을 세우고, 문서화한다 | F16: FALSE | P16: 1 | Q16: =IF(F16=TRUE,P16,0) -> 0 | R16: 사업계획을 팀원과 공유하며 주기적으로 검토해야함 | U16: 사업활동 | V16: 기업의 사회적가치 | W16: 근로자 보건 및 안전 운영 | X16: 1단계 | Y16: =Q19 -> 0.5 | Z16: =AVERAGE(Y16:Y22) -> 2.5 | AB16: 3 | AC16: =VLOOKUP(Y16,Q20:R23,2,0) -> 업무재해 위험 요소를 파악하여 안전 교육을 실시하고
C17: ㄴ 3. 연초에 사업계획을 세우고, 문서화하여 기업 구성원(팀원, 직원 등)과 공유한다 | F17: FALSE | P17: 4 | Q17: =IF(F17=TRUE,P17,0) -> 0 | R17: 사업계획 내 성과 지표를 설정하며 목표 달성을 위한 실행 계획수립을 권장함 | W17: 사회적 가치 실천_근로자 권리 및 역량향상 | X17: 2단계
C18: ㄴ 4. 연초 사업계획을 세우고, 문서화하여 기업 구성원과 공유하며, 경제적, 사회적 성과지표가 명확하다 | F18: TRUE | P18: 5 | Q18: =IF(F18=TRUE,P18,0) -> 5 | R18: 사업성과를 정기적으로 평가하며 피드백을 통해 계획을 보완하여야함 | W18: 사업의 사회적가치 | X18: 1단계 | Y18: =Q24 -> 2.5 | AB18: 4 | AC18: =VLOOKUP(Y18,Q25:R28,2,0) -> 상품 가격 경쟁력을 유지하고 품질보장 방법을 모색해야함
A19: 1단계 | B19: 3 | C19: 근로자들의 보건 및 안전에 대한 관한 질문입니다 | E19: =IF(COUNTIF(F20:F23,TRUE)=0,"체크해주세요",IF(COUNTIF(F20:F23,TRUE)>1,"하나만 선택하세요","")) | P19: 3 | Q19: =SUM(Q20:Q23) -> 0.5 | V19: 사회적경제기업 협력 | W19: 사회적경제기업 협력 | X19: 1단계 | Y19: =Q29 -> 5 | AB19: 5,6 | AC19: =IF(SUM($Q$30:$Q$33)=0,$R$30,IF(SUM($Q$30:$Q$33)=0.5,$R$31,IF(SUM($Q$30:$Q$33)=1,$R$32,$R$33))) &" "& IF(SUM($Q$35:$Q$38)=0,$R$35,IF(SUM($Q$35:$Q$38)=1,$R$36,IF(SUM($Q$35:$Q$38)=2,$R$37,$R$38))) -> 사회적경제기업과 협력사업을 확대하며 지속가능한 관계를 구축하고 사회적경제기업과 협력 성과를 평가하며 지속가능한 관계를 유지하고
C20: ㄴ 1.업무 수행상 발생가능한 재해(사고, 질병)의 종류와 위치, 상황 등을 거의 확인하지 않고 있다 | F20: TRUE | P20: 0.5 | Q20: =IF(F20=TRUE,P20,0) -> 0.5 | R20: 업무재해 위험 요소를 파악하여 안전 교육을 실시하고 | V20: 지역협력 | W20: 지역협력 | X20: 1단계 | Y20: =Q39 -> 0.5 | AB20: 7 | AC20: =VLOOKUP(Y20,Q40:R43,2,0) -> 지역기업과의 거래를 우선하여 지역경제 활성화에 기여해야함
C21: ㄴ 2. 업무 수행상 발생가능한 재해(사고, 질병)의 종류와 위치, 상황 등을 확인하고 있긴 하나 구체적으로 대비하고 있지 않다 | F21: FALSE | P21: 1 | Q21: =IF(F21=TRUE,P21,0) -> 0 | R21: 근로자를 위한 업무재해 위험요소의 대비책 마련을 하고 | V21: 사회환원 | W21: 사회환원계획 (사회적 투자 계획, 사회서비스 활동) | X21: 1단계 | Y21: =Q44 -> 4 | AB21: 8,9 | AC21: =IF(SUM($Q$45:$Q$48)=0.5,$R$45,IF(SUM($Q$45:$Q$48)=1,$R$46,IF(SUM($Q$45:$Q$48)=4,$R$47,$R$48))) &" "& IF(SUM($Q$50:$Q$53)=0.5,$R$50,IF(SUM($Q$50:$Q$53)=1,$R$51,IF(SUM($Q$50:$Q$53)=4,$R$52,$R$53))) -> 사회적환원 비율을 높이기위한 계획 수립과 실행을하고 정기적 사회서비스 제공 활동으로 지속적 지원체계를 구축해야함
C22: ㄴ 3. 업무 수행상 발생가능한 재해(사고, 질병)의 종류와 위치, 상황 등을 확인하고 있으며, 산업안전보건교육을 포함해 일부를 지원하고 있다 | F22: FALSE | P22: 4 | Q22: =IF(F22=TRUE,P22,0) -> 0 | R22: 근로자 안전을 위한 체계적인 교육 시스템을 구축하고 | W22: 사회적이익 | X22: 2단계
C23: ㄴ 4. 업무 수행상 발생가능한 재해(사고, 질병)의 종류와 위치, 상황 등을 대비하고 있으며, 산업안전보건교육을 포함해 대부분을 지원하고 있다 | F23: FALSE | P23: 5 | Q23: =IF(F23=TRUE,P23,0) -> 0 | R23: 근로자 안전을 위한 안전 문화를 정착시키고 | U23: 조직운영 | V23: 조직 거버넌스 | W23: 민주적 의사결정 구조 | X23: 1단계 | Y23: =Q54 -> 5 | Z23: =AVERAGE(Y23:Y27) -> 2.8333333 | AB23: 10 | AC23: =VLOOKUP(Y23,Q55:R59,2,0) -> 근로자들이 회의결과에 대해 의견을 제시할 수 있는 기회를 제공하고
A24: 1단계 | B24: 4 | C24: 사업의 사회적가치에 관한 질문입니다. 해당사항을 모두 선택해주세요. | E24: =IF(COUNTIF(F25:F28,TRUE)=0,"해당사항을 모두 체크해주세요","") | P24: 4 | Q24: {=SUM(F25:F28*1.25)} -> 2.5 | V24: 고용 | W24: 고용계획 | X24: 1단계 | Y24: =Q60 -> 0.5 | AB24: 11 | AC24: =VLOOKUP(Y24,Q61:R66,2,0) -> 고용 계획 수립과 인력확보 방안 모색이 필요함
C25: ㄴ 1. 시장에서 목표대상고객(지역)에게 잘 공급되지 않는 제품과 서비스를 공급하고 있다 | F25: FALSE | P25: =5/4 -> 1.25 | Q25: 1.25 | R25: 상품의 차별성을 강조하며 마케팅 전략을 강화해야함 | W25: 고용운영(인사·복리후생 규정) | X25: 2단계
C26: ㄴ 2. 목표대상고객에게 시장 평균보다 저렴한 가격으로 제품과 서비스를 공급하고 있다 | F26: TRUE | P26: =5/4 -> 1.25 | Q26: =1.25*2 -> 2.5 | R26: 상품 가격 경쟁력을 유지하고 품질보장 방법을 모색해야함 | V26: 내부역량향상 | W26: 교육참여 | X26: 1단계 | Y26: =Q67 -> 3 | AB26: 12,13 | AC26: =IF(SUM(Q68:Q71)=0,R68,IF(SUM(Q68:Q71)=0.5,R69,IF(SUM(Q68:Q71)=0,R70,R71)&" "&IF(SUM(Q73:Q76)=0,R73,IF(SUM(Q73:Q76)=1,R74,IF(SUM(Q73:Q76)=2,R75,R76))))) -> 이슈현황을 문서화하여 체계적으로 관리하고 대표자가 교육내용을 기업에 적용할 수 있도록함
C27: ㄴ 3. 제품과 서비스를 생산하고 판매하기 위해 취약계층을 고용하고 있다 | F27: TRUE | P27: =5/4 -> 1.25 | Q27: =1.25*3 -> 3.75 | R27: 지속적인 취약계층의 고용을 유지하길 권장함 | W27: 근로자교육 | X27: 2단계
C28: ㄴ 4. 제품과 서비스를 생산하고 판매하는 데 있어서 지역의 자원을 주로 활용하고 있다 | F28: FALSE | P28: =5/4 -> 1.25 | Q28: =1.25*4 -> 5 | R28: 지역 자원의 활용도 증대와 지역 사회와의 협력을 강화해야함 | T28: 경제적성과 | U28: 재정성과 | V28: 비즈니스모델 | W28: 비즈니스모델 | X28: 1단계 | Y28: =Q77 -> 1 | Z28: =AVERAGE(Y28:Y31) -> 3 | AA28: =AVERAGE(Z28:Z31) -> 3 | AB28: 14 | AC28: =VLOOKUP($Y$28,$Q$78:$R$83,2,0) -> 제품/서비스 프로토타입 제작과 테스트를 실시하며 개선하고
A29: 1단계 | B29: 5 | C29: 사회적경제기업과 협력활동에 관한 질문입니다 | E29: =IF(COUNTIF(F30:F33,TRUE)=0,"체크해주세요",IF(COUNTIF(F30:F33,TRUE)>1,"하나만 선택하세요","")) | P29: 5, 6번 | Q29: =SUM(Q30:Q38) -> 5 | W29: 지원사업참여 | X29: 1단계 | Y29: =Q84 -> 5 | AB29: 15 | AC29: =VLOOKUP($Y$29,$Q$85:$R$88,2,0) -> 지원사업 종료 후의 후속사업을 준비해야함
C30: ㄴ 1. 사회적경제기업 당사자 모임(협의회)이 있는지 모른다 | F30: FALSE | P30: 0 | Q30: =IF(F30=TRUE,P30,0) -> 0 | R30: 사회적경제 협력활동 관련정보를 조사하며 참여기회를 찾고 | W30: 마케팅 계획 | X30: 2단계
C31: ㄴ 2. 사회적경제기업 당사자 모임(협의회)이 있는지는 알고 있으나 활동하진 않는다 | F31: FALSE | P31: 0.5 | Q31: =IF(F31=TRUE,P31,0) -> 0 | R31: 사회적경제 협력활동 모임에 적극참여하며 협력기회를 모색하고 | V31: 경제적성과 | W31: 고정매출 발생(지속발전) | X31: 2단계
C32: ㄴ 3. 사회적경제기업 당사자 모임(협의회)의 회원이며 회의에 참석한다 | F32: FALSE | P32: 1 | Q32: =IF(F32=TRUE,P32,0) -> 0 | R32: 사회적경제 협력 회원사들과 실질적 협력 방안을 마련하고 | T32: 혁신성과 | U32: 기업혁신 | V32: 성장잠재력 | W32: 성장잠재력 | X32: 1단계 | Y32: =Q90 -> 5 | Z32: =AVERAGE(Y32:Y37) -> 4 | AA32: =AVERAGE(Z32:Z37) -> 4 | AB32: 16 | AC32: =VLOOKUP($Y$32,$T$94:$U$98,2,0) -> 혁신적인 프로젝트를 통해 새로운 시장 진입을 적극적으로 시도하고
C33: ㄴ 4. 사회적경제기업 당사자 모임(협의회)의 회원으로 기업들 간 봉사활동, 공동사업, 마켓운영 등 협력사업을 연 1회 이상 진행한다 | F33: TRUE | P33: 1.5 | Q33: =IF(F33=TRUE,P33,0) -> 1.5 | R33: 사회적경제기업과 협력사업을 확대하며 지속가능한 관계를 구축하고 | V33: 사업아이템 | W33: 아이템경쟁력 | X33: 1단계 | Y33: =Q91 -> 3 | AB33: 17 | AC33: =VLOOKUP($Y$33,$V$94:$W$98,2,0) -> 정기적으로 경쟁사 모니터링을 실시하여 시장 변화에 신속하게 대응하고
B34: 6 | C34: 사회적경제기업과 거래활동에 관한 질문입니다 | E34: =IF(COUNTIF(F35:F38,TRUE)=0,"체크해주세요",IF(COUNTIF(F35:F38,TRUE)>1,"하나만 선택하세요","")) | W34: 아이템검증 | X34: 2단계
C35: ㄴ 1. 우리 회사와 사업상 거래를 할 수 있는 사회적경제기업을 모른다 | F35: FALSE | P35: 0.5 | Q35: =IF(F35=TRUE,P35,0) -> 0 | R35: 사회적경제기업 관련 기업을 조사하며 거래 기회를 찾아 | V35: 시장분석 | W35: 시장분석계획 | X35: 1단계 | Y35: =Q92 -> 4 | AB35: 18 | AC35: =VLOOKUP($Y$35,$X$94:$Y$98,2,0) -> 점검, 분석결과를 통해 대응방안을 마련한다
C36: ㄴ 2. 우리 회사와 사업상 거래를 할 수 있는 사회적경제기업을 알고 있으나 거래를 하지는 않았다 | F36: FALSE | P36: 1 | Q36: =IF(F36=TRUE,P36,0) -> 0 | R36: 사회적경제기업과 거래 조건을 검토하며 협력방안을 논의하고 | W36: 시장분석실천 | X36: 2단계
C37: ㄴ 3. 사회적경제기업과 협력을 강화하기 위해 상호거래 및 업무협약 등 최근 1년 이내 실행한 사례가 있다 | F37: FALSE | P37: 2 | Q37: =IF(F37=TRUE,P37,0) -> 0 | R37: 사회적경제기업과 협력사례를 분석하며 추가 협력방안을 모색하고 | V37: 혁신노력 | W37: 혁신노력 | X37: 2단계
A38: 1단계 | C38: ㄴ 4. 사회적경제기업과 협력을 강화하기 위해 상호거래 및 업무협약 등 최근 1년 이내 다수 진행하였다 | F38: TRUE | P38: 3.5 | Q38: =IF(F38=TRUE,P38,0) -> 3.5 | R38: 사회적경제기업과 협력 성과를 평가하며 지속가능한 관계를 유지하고 | T38: 3관점, 5개범주 | V38: =COUNTA(V12:V37) -> 15 | W38: =COUNTA(W12:W37) -> 26 | Y38: =SUM(Y12:Y37)/75*100 -> 64
B39: 7 | C39: 지역 네트워크활동에 관한 질문입니다 | E39: =IF(COUNTIF(F40:F43,TRUE)=0,"체크해주세요",IF(COUNTIF(F40:F43,TRUE)>1,"하나만 선택하세요","")) | P39: 7 | Q39: =SUM(Q40:Q43) -> 0.5
C40: ㄴ 1. 거래에 있어 지역을 크게 신경쓰지 않는 편이다 | F40: TRUE | P40: 0.5 | Q40: =IF(F40=TRUE,P40,0) -> 0.5 | R40: 지역기업과의 거래를 우선하여 지역경제 활성화에 기여해야함
A41: 1단계 | C41: ㄴ 2. 우리 지역 기업/기관과 거래하기 위해 탐색한 적은 있지만 아직 거래한 적이 없다 | F41: FALSE | P41: 1 | Q41: =IF(F41=TRUE,P41,0) -> 0 | R41: 지역기업과의 구체적인 계획을 수립하며 협력을 강화해야함 | U41: 그래프1 | V41: 요인 | W41: 해당점수 | X41: 1.7미만 | Y41: 3.4미만 | Z41: 이상 | AA41: 요인
C42: ㄴ 3. 우리 지역 기업/기관과 거래하기 위해 탐색하고 거래를 하였다 | F42: FALSE | P42: 4 | Q42: =IF(F42=TRUE,P42,0) -> 0 | R42: 지역거래 기업과의 관계를 지속적으로 발전시키길 권장함 | U42: 조직미션 | V42: 소셜미션 | W42: =Y12 -> 4 | X42: =IF(W42<1.7,W42,"") | Y42: =IF(AND(W42>=1.7,W42<3.4),W42,"") | Z42: =IF(W42>=3.4,W42,"") -> 4 | AA42: 소셜미션
...

Sheet 결과보고서
B2: 입주기업 기초진단 결과보고서
B4: 기업명 | F4: =기초진단!E3 -> 협동조합 가나다 | Q4: 자가진단일 | U4: =기초진단!E2 -> 44906 | AG4: 기업은 진단 결과를 확인하며 요청사항에 대해 의견
B6: 담당 | F6: =기초진단!E4 -> 강호동 대표 | Q6: 진단일 | U6: <면담일 기입>
B8: =""&F4&" 기업을 기초진단한 결과 가장 취약한 영역은 "&기초진단!W65&"입니다" -> 협동조합 가나다 기업을 기초진단한 결과 가장 취약한 영역은 경제적성과입니다
B9: ="세부적으로 살펴보면 상대적으로 "&기초진단!X65&" 요인이 낮습니다. 하지만 "&기초진단!X67&" 요인은 긍정적으로 높게 나타났습니다. 그리고 "&기초진단!AC10&" 확인하였습니다." -> 세부적으로 살펴보면 상대적으로 지역협력 요인이 낮습니다. 하지만 사업계획수립 요인은 긍정적으로 높게 나타났습니다. 그리고 사업경험도 있고 동종업종 경험도 있음을 확인하였습니다.
R14: =VLOOKUP(기초진단!Y57,기초진단!Q93:R125,2,0) -> 사업활동 영역 강화가 필요합니다. 사회적 가치 창출을 위한 구체적 사업계획 수립과 실행방안 모색이 요구됩니다. 명확한 목표 설정과 성과 측정을 통해 지속적으로 개선해 나가야 합니다. 이를 위해 시장 조사 및 분석을 통해 고객의 요구와 사회적 문제를 파악하고, 이를 해결하기 위한 혁신적인 사업 모델을 개발해야 합니다. 또한, 사업 성과를 정기적으로 평가하여 필요한 조정을 통해 목표 달성을 촉진해야 합니다.
B27: [소셜미션· 사업계획수립] | AG27: 기업의 진단 결과를 확인하며 면담하여 담당자의 의견 서술
B28: =IFERROR(기초진단!$AC$12 &" "& 기초진단!$AC$14,"선택을 다시 확인하세요") -> 사회적문제 해결을 위한 계획과 목표달성을 위한 세부전략을 마련하고 사업성과를 정기적으로 평가하며 피드백을 통해 계획을 보완하여야함
B32: [기업의 사회적가치·사회적경제기업협력·지역협력 ]
B33: =IFERROR(기초진단!$AC$16 &" " &기초진단!$AC$18 & ". 또한, "& 기초진단!$AC$19 & " " &기초진단!$AC$20,"선택을 다시 확인하세요") -> 업무재해 위험 요소를 파악하여 안전 교육을 실시하고 상품 가격 경쟁력을 유지하고 품질보장 방법을 모색해야함. 또한, 사회적경제기업과 협력사업을 확대하며 지속가능한 관계를 구축하고 사회적경제기업과 협력 성과를 평가하며 지속가능한 관계를 유지하고 지역기업과의 거래를 우선하여 지역경제 활성화에 기여해야함
B40: [사회환원 ]
B41: =IFERROR(기초진단!$AC$21,"선택을 다시 확인하세요") -> 사회적환원 비율을 높이기위한 계획 수립과 실행을하고 정기적 사회서비스 제공 활동으로 지속적 지원체계를 구축해야함
B44: [ 민주적 의사결정·고용·교육 ]
B45: =IFERROR(기초진단!AC23 &" " &기초진단!AC24 &". 그리고 "& 기초진단!AC26,"선택을 다시 확인하세요") -> 근로자들이 회의결과에 대해 의견을 제시할 수 있는 기회를 제공하고 고용 계획 수립과 인력확보 방안 모색이 필요함. 그리고 이슈현황을 문서화하여 체계적으로 관리하고 대표자가 교육내용을 기업에 적용할 수 있도록함
B51: [ 비즈니스모델과 ]
B52: =IFERROR(기초진단!AC28 &" "& 기초진단!AC29, "선택을 다시 확인하세요") -> 제품/서비스 프로토타입 제작과 테스트를 실시하며 개선하고 지원사업 종료 후의 후속사업을 준비해야함
B55: [ 성장잠재력·사업아이템· 시장분석 ]
B56: =IFERROR(기초진단!AC32 &" "& 기초진단!AC33 & " "& 기초진단!AC35,"선택을 다시 확인하세요") -> 혁신적인 프로젝트를 통해 새로운 시장 진입을 적극적으로 시도하고 정기적으로 경쟁사 모니터링을 실시하여 시장 변화에 신속하게 대응하고 점검, 분석결과를 통해 대응방안을 마련한다

Sheet 심화진단
D2: 일시 | E2: 45606
D3: 기업명 | E3: 협동조합 가나다라
D4: 작성자 | E4: 대표 홍길동
A6: 연번 | B6: 질문 | O6: 점수체계 | P6: 해당점수 | Q6: 코멘트 | S6: 하나만 선택하세요
A7: 확인 | B7: 과거에 사업경험이 있다 | C7: =IF(COUNTIF(D7:H7,TRUE)=0,"체크해주세요",IF(COUNTIF(D7:H7,TRUE)>1,"하나만 선택하세요","")) | D7: 있다 | E7: TRUE | F7: 없다 | G7: FALSE | Q7: =IF(AND(E7=TRUE,E8=TRUE),"사업경험도 있고 동종업종 경험도 있음을",IF(AND(E7=TRUE,E8=FALSE),"사업경험도 있음을",IF(AND(E7=FALSE,E8=TRUE),"사업경험은 없으나 동종업종 경험이 있음을","사업경험이나 동종업종 경험이 없음을"))) -> 사업경험도 있고 동종업종 경험도 있음을
A8: 확인 | B8: 해당 업계에 종사한 경험이 있다 | C8: =IF(COUNTIF(D8:H8,TRUE)=0,"체크해주세요",IF(COUNTIF(D8:H8,TRUE)>1,"하나만 선택하세요","")) | D8: 있다 | E8: TRUE | F8: 없다 | G8: FALSE
A9: 1 | B9: 해결하고자 하는 사회적문제에 대한 해결방안 계획에 대한 질문입니다 | D9: =IF(COUNTIF(E10:E13,TRUE)=0,"체크해주세요",IF(COUNTIF(E10:E13,TRUE)>1,"하나만 선택하세요","")) | O9: 1 | P9: =SUM(P10:P13) -> 5 | S9: 관점 | T9: 범주 | U9: 요인 | V9: 하위요인 | W9: 단계 | X9: No | Y9: 해당점수 | Z9: 범주점수 | AA9: 관점점수 | AB9: 코멘트
B10: ㄴ 1. 해결하고자 하는 사회적 문제가 있지만 아직 명확하지 않다 | E10: FALSE | O10: 0.5 | P10: =IF(E10=TRUE,O10,0) -> 0 | Q10: 해결하고자 하는 사회적문제를 명확히 정의하고 | S10: 확인 | U10: 사업경험 | V10: 사업경험 | W10: 사업경험 | AB10: =IF(AND(E7=TRUE,E8=TRUE),"사업경험도 있고 동종업종 경험도 있음을",IF(AND(E7=TRUE,E8=FALSE),"사업경험도 있음을",IF(AND(E7=FALSE,E8=TRUE),"사업경험은 없으나 동종업종 경험이 있음을","사업경험이나 동종업종 경험이 없음을"))) -> 사업경험도 있고 동종업종 경험도 있음을
B11: ㄴ 2. 해결하고자 하는 사회적 문제가 분명하지만 아직 구체적인 해결 계획은 없다 | E11: FALSE | O11: 1 | P11: =IF(E11=TRUE,O11,0) -> 0 | Q11: 사회적문제 해결을 위한 구체적 해결 계획을 수립하고 | U11: 동종업종경험 | V11: 동종업종경험 | W11: 동업종경험
B12: ㄴ 3. 해결하고자 하는 사회적 문제가 분명하고 구체적인 해결 계획을 가지고 있다 | E12: FALSE | O12: 4 | P12: =IF(E12=TRUE,O12,0) -> 0 | Q12: 사회적문제 해결을 위한 목표달성을 위해 세부전략을 마련하고 | S12: 사회적성과 | T12: 조직미션 | U12: 소셜미션 | V12: 소셜미션 | W12: 1단계 | X12: 1 | Y12: =P9 -> 5 | Z12: =AVERAGE(Y12:Y15) -> 3.25 | AA12: =AVERAGE(Z12:Z27) -> 3.1142857 | AB12: =VLOOKUP(Y12,P10:Q13,2,0) -> 사회적문제 해결을 위한 시도의 결과를 분석하며 개선점을 도출하고
B13: ㄴ 4. 해결하고자 하는 사회적 문제가 분명하고 계획이 구체적이며, 이에 따른 여러가지 시도를 해봤다 | E13: TRUE | O13: 5 | P13: =IF(E13=TRUE,O13,0) -> 5 | Q13: 사회적문제 해결을 위한 시도의 결과를 분석하며 개선점을 도출하고 | V13: 소셜미션실천 | W13: 2단계 | X13: 2 | Y13: =P14 -> 1 | AB13: =VLOOKUP(Y13,P15:Q19,2,0) -> 소셜미션을 구체적으로 수립하며
A14: 2 | B14: 기업의 소셜미션과 비전에 대한 실천정도에 대한 질문입니다 | D14: =IF(COUNTIF(E15:E19,TRUE)=0,"체크해주세요",IF(COUNTIF(E15:E19,TRUE)>1,"하나만 선택하세요","")) | O14: 2 | P14: =SUM(P15:P19) -> 1 | U14: 성과관리체계 | V14: 사업계획수립 | W14: 1단계 | X14: 3 | Y14: =P20 -> 5 | AB14: =VLOOKUP(Y14,P21:Q24,2,0) -> 정기적인 사업성과평가와 피드백을 통해 보완하여야함
B15: ㄴ 1. 기업의 소셜미션과 비전이 없거나 아직 정하지 않은 상태다 | E15: FALSE | O15: 0.5 | P15: =IF(E15=TRUE,O15,0) -> 0 | Q15: 소셜미션을 설정하며 | V15: 성과관리 (중간점검 및 결과분석) | W15: 2단계 | X15: 4 | Y15: =P25 -> 2 | AB15: =VLOOKUP(Y15,P26:Q30,2,0) -> 직원들과 정기적회의를 진행하며 관리해야함
B16: ㄴ 2. 기업의 소셜미션과 비전이 있으나 인증유형 수준(일자리창출, 사회서비스제공 등)으로 구체적이지 않다 | E16: TRUE | O16: 1 | P16: =IF(E16=TRUE,O16,0) -> 1 | Q16: 소셜미션을 구체적으로 수립하며 | T16: 사업활동 | U16: 기업의 사회적가치 | V16: 근로자 보건 및 안전 운영 | W16: 1단계 | X16: 5 | Y16: =P31 -> 5 | Z16: =AVERAGE(Y16:Y22) -> 2.8928571 | AB16: =VLOOKUP(Y16,P32:Q35,2,0) -> 근로자 안전을 위한 지속적인 교육&훈련을 통해 안전 문화를 정착으로
B17: ㄴ 3. 기업의 소셜미션과 비전이 구체적이나 명문화 되어 있지 않다 | E17: FALSE | O17: 2 | P17: =IF(E17=TRUE,O17,0) -> 0 | Q17: 수립된 소셜미션을 명문화하고 | V17: 사회적 가치 실천_근로자 권리 및 역량향상 | W17: 2단계 | X17: 6 | Y17: =P36 -> 2.5 | AB17: =IF(Y17>4,Q39,IF(Y17>2,Q38,Q37)) -> 근로자 권리 및 역량향상에 대한 노력을 하고 있음
B18: ㄴ 4. 기업의 소셜미션과 비전이 구체적이고 정관을 포함한 내부문서로만 명문화 되어 있다 | E18: FALSE | O18: 3 | P18: =IF(E18=TRUE,O18,0) -> 0 | Q18: 소셜미션을 대외적으로 공표하고 | V18: 사업의 사회적가치 | W18: 1단계 | X18: 7 | Y18: =P43 -> 5 | AB18: =VLOOKUP(Y18,P44:Q47,2,0) -> 지역 자원의 활용도 증대와 지역 사회와의 협력을 강화해야함
B19: ㄴ 5. 기업의 소셜미션과 비전이 구체적이고 정관을 포함한 내부문서 및 홈페이지, SNS 등 대외적으로 공표하고 있다 | E19: FALSE | O19: 5 | P19: =IF(E19=TRUE,O19,0) -> 0 | Q19: 소셜미션을 수행하며 | U19: 사회적경제기업 협력 | V19: 사회적경제기업 협력 | W19: 1단계 | X19: 8, 9 | Y19: =P48 -> 4.5 | AB19: =IF(Y19>4,Q51,IF(Y19>2,Q50,Q49)) -> 사회적경제기업과 협력사업을 확대하며 지속가능한 관계를 구축하고
A20: 3 | B20: 사업계획에 대한 질문입니다 | D20: =IF(COUNTIF(E21:E24,TRUE)=0,"체크해주세요",IF(COUNTIF(E21:E24,TRUE)>1,"하나만 선택하세요","")) | O20: 3 | P20: =SUM(P21:P24) -> 5 | U20: 지역협력 | V20: 지역협력 | W20: 1단계 | X20: 10 | Y20: =P58 -> 0.5 | AB20: =VLOOKUP(Y20,P59:Q62,2,0) -> 지역기업과의 거래를 우선하여 지역경제 활성화에 기여해야함
B21: ㄴ 1. 연초에 사업계획을 세운다 | E21: FALSE | O21: 0.5 | P21: =IF(E21=TRUE,O21,0) -> 0 | Q21: 사업계획 목표와 전략을 명확히 문서화하여 공유해야함 | U21: 사회환원 | V21: 사회환원계획 (사회적 투자 계획, 사회서비스 활동) | W21: 1단계 | X21: 11,12 | Y21: =P63 -> 2.25 | AB21: =IF(Y21>4,Q66,IF(Y21>2,Q65,Q64)) -> 사회적환원 비율을 높이고 계획을 수립하며 실행하고
B22: ㄴ 2. 연초에 사업계획을 세우고, 문서화한다 | E22: FALSE | O22: 1 | P22: =IF(E22=TRUE,O22,0) -> 0 | Q22: 사업계획을 팀원과 공유하며 주기적으로 검토해야함 | V22: 사회적이익 | W22: 2단계 | X22: 13 | Y22: =P73 -> 0.5 | AB22: =VLOOKUP(Y22,P74:Q77,2,0) -> 지역사회 기부나 사회공헌사업에 대해 관심을 가질 필요가 있음
B23: ㄴ 3. 연초에 사업계획을 세우고, 문서화하여 기업 구성원(팀원, 직원 등)과 공유한다 | E23: FALSE | O23: 4 | P23: =IF(E23=TRUE,O23,0) -> 0 | Q23: 사업계획 내 성과지표 설정과 목표달성 실행 계획수립 권장함 | T23: 조직운영 | U23: 조직 거버넌스 | V23: 민주적 의사결정 구조 | W23: 1단계 | X23: 14 | Y23: =P78 -> 5 | Z23: =AVERAGE(Y23:Y27) -> 3.2 | AB23: =VLOOKUP(Y23,P79:Q83,2,0) -> 근로자들이 회의결과에 대해 의견을 제시할 수 있는 기회를 제공하고
B24: ㄴ 4. 연초 사업계획을 세우고, 문서화하여 기업 구성원과 공유하며, 경제적, 사회적 성과지표가 명확하다 | E24: TRUE | O24: 5 | P24: =IF(E24=TRUE,O24,0) -> 5 | Q24: 정기적인 사업성과평가와 피드백을 통해 보완하여야함 | U24: 고용 | V24: 고용계획 | W24: 1단계 | X24: 15 | Y24: =P84 -> 0.5 | AB24: =VLOOKUP(Y24,P85:Q90,2,0) -> 고용 계획 수립과 인력확보 방안 모색이 필요함
A25: 4 | B25: 사업계획 대비 성과를 확인하기 위해 직원들과 성과관리를 하는지에 대한 질문입니다 | D25: =IF(COUNTIF(E26:E30,TRUE)=0,"체크해주세요",IF(COUNTIF(E26:E30,TRUE)>1,"하나만 선택하세요","")) | O25: 4 | P25: =SUM(P26:P30) -> 2 | V25: 고용운영(인사·복리후생 규정) | W25: 2단계 | X25: 16 | Y25: =P91 -> 2 | AB25: =VLOOKUP(Y25,P92:Q97,2,0) -> 근로자 근로조건은 우수하나 복리후생비, 성과급 등 임금체계에 대한 향상을 권장함
B26: ㄴ 1. 직원들과 별도 회의를 진행하지 않고 대표가 필요시 성과관리를 한다. | E26: FALSE | O26: 0.5 | P26: =IF(E26=TRUE,O26,0) -> 0 | Q26: 직원들과 정기적회의를 진행하고 | U26: 내부역량향상 | V26: 교육참여 | W26: 1단계 | X26: 17,18 | Y26: =P98 -> 4.5 | AB26: =IF(Y26>4,Q101,IF(Y26>2,Q100,Q99)) -> 대표자의 교육수료 내용을 구성원들과 공유하길 권장함
B27: ㄴ 2. 성과관리를 위해 직원들과 비정기적으로 회의를 진행하나 별도 문서화 하여 관리하지 않는다 | E27: FALSE | O27: 1 | P27: =IF(E27=TRUE,O27,0) -> 0 | Q27: 직원들과 정기적회의를 진행하고 | V27: 근로자교육 | W27: 2단계 | X27: 19 | Y27: =P108 -> 4 | AB27: =VLOOKUP(Y27,P109:Q113,2,0) -> 근로자의 역량향상을 위한 교육계획 및 실천을 권장함
B28: ㄴ 3. 성과관리를 위해 직원들과 비정기적으로 회의를 진행하고 문서화 하여 관리한다 | E28: TRUE | O28: 2 | P28: =IF(E28=TRUE,O28,0) -> 2 | Q28: 직원들과 정기적회의를 진행하며 관리해야함 | S28: 경제적성과 | T28: 재정성과 | U28: 비즈니스모델 | V28: 비즈니스모델 | W28: 1단계 | X28: 20 | Y28: =P114 -> 2 | Z28: =AVERAGE(Y28:Y31) -> 3.25 | AA28: =AVERAGE(Z28:Z31) -> 3.25 | AB28: =VLOOKUP(Y28,P115:Q120,2,0) -> 상품의 안정적인 공급망 유지 및 품질관리를 위해 노력하고,
B29: ㄴ 4. 성과관리를 위해 직원들과 정기적으로 회의를 진행하나 문서화하여 관리하진 않는다 | E29: FALSE | O29: 3 | P29: =IF(E29=TRUE,O29,0) -> 0 | Q29: 성과관리 회의를 문서화해야함 | V29: 지원사업참여 | W29: 1단계 | X29: 21 | Y29: =P121 -> 4 | AB29: =VLOOKUP(Y29,P122:Q125,2,0) -> 지원사업 경험을 바탕으로 지속 가능한 수익모델을 개발해야함
B30: ㄴ 5. 성과관리를 위해 직원들과 정기적으로 회의를 진행하고 문서화하여 관리한다 | E30: FALSE | O30: 5 | P30: =IF(E30=TRUE,O30,0) -> 0 | Q30: 성과관리를 잘하고 있으며 | V30: 마케팅 계획 | W30: 2단계 | X30: 22 | Y30: =P126 -> 2 | AB30: =IF(Y30>4,Q129,IF(Y30>2,Q128,Q127)) -> 시장을 세분화하고, 타켓 시장을 설정하여 상품 포지션을 찾는 마케팅 계획을 수립해야함
A31: 5 | B31: 근로자들의 보건 및 안전에 대한 관한 질문입니다 | D31: =IF(COUNTIF(E32:E35,TRUE)=0,"체크해주세요",IF(COUNTIF(E32:E35,TRUE)>1,"하나만 선택하세요","")) | O31: 5 | P31: =SUM(P32:P35) -> 5 | U31: 경제적성과 | V31: 고정매출 발생(지속발전) | W31: 2단계 | X31: 23 | Y31: =P133 -> 5 | AB31: =VLOOKUP(Y31,P134:Q137,2,0) -> 고정매출로 우수한 경제적성과를 이루고 있음
B32: ㄴ 1.업무 수행상 발생가능한 재해(사고, 질병)의 종류와 위치, 상황 등을 거의 확인하지 않고 있다 | E32: FALSE | O32: 0.5 | P32: =IF(E32=TRUE,O32,0) -> 0 | Q32: 근로자를 위한 재해 위험 요소를 파악하여 안전교육을 실시로 | S32: 혁신성과 | T32: 기업혁신 | U32: 성장잠재력 | V32: 성장잠재력 | W32: 1단계 | X32: 24 | Y32: =P139 -> 5 | Z32: =AVERAGE(Y32:Y37) -> 3.5 | AA32: =AVERAGE(Z32:Z37) -> 3.5 | AB32: =VLOOKUP($Y32,$S$139:$T$143,2,0) -> 혁신적인 프로젝트를 통해 새로운 시장 진입을 적극적으로 시도하고
B33: ㄴ 2. 업무 수행상 발생가능한 재해(사고, 질병)의 종류와 위치, 상황 등을 확인하고 있긴 하나 구체적으로 대비하고 있지 않다 | E33: FALSE | O33: 1 | P33: =IF(E33=TRUE,O33,0) -> 0 | Q33: 근로자를 위한 업무재해 위험요소의 대비책 마련으로 | U33: 사업아이템 | V33: 아이템경쟁력 | W33: 1단계 | X33: 25 | Y33: =P140 -> 1 | AB33: =VLOOKUP($Y33,$U$139:$V$143,2,0) -> 경쟁사의 성공 사례를 벤치마킹하여 전략을 수립하고
B34: ㄴ 3. 업무 수행상 발생가능한 재해(사고, 질병)의 종류와 위치, 상황 등을 확인하고 있으며, 산업안전보건교육을 포함해 일부를 지원하고 있다 | E34: FALSE | O34: 4 | P34: =IF(E34=TRUE,O34,0) -> 0 | Q34: 근로자 안전을 위한 체계적인 교육운영 및 시스템을 구축으로 | V34: 아이템검증 | W34: 2단계 | X34: 26 | Y34: =P141 -> 3 | AB34: =VLOOKUP($Y34,$Y$139:$Z$143,2,0) -> 업계 트랜드 분석후 적용 가능한 기술을 확인해볼수 있음
B35: ㄴ 4. 업무 수행상 발생가능한 재해(사고, 질병)의 종류와 위치, 상황 등을 대비하고 있으며, 산업안전보건교육을 포함해 대부분을 지원하고 있다 | E35: TRUE | O35: 5 | P35: =IF(E35=TRUE,O35,0) -> 5 | Q35: 근로자 안전을 위한 지속적인 교육&훈련을 통해 안전 문화를 정착으로 | U35: 시장분석 | V35: 시장분석계획 | W35: 1단계 | X35: 27 | Y35: =P142 -> 4 | AB35: =VLOOKUP($Y35,$W$139:$X$143,2,0) -> 점검, 분석결과를 통해 대응방안을 마련한다
A36: 6 | B36: 근로자 권리 및 역량향상에 관한 질문입니다. 해당되는 사항을 모두 선택해주세요 | D36: =IF(COUNTIF(E37:E42,TRUE)=0,"해당사항을 모두 체크해주세요","") | O36: 6 | P36: =SUM(P37:P42) -> 2.5 | Q36: 1점이하,2~4/ 4점이상 | V36: 시장분석실천 | W36: 2단계 | X36: 28 | Y36: =P143 -> 5 | AB36: =VLOOKUP($Y36,$AA$139:$AB$143,2,0) -> 시장 변화에 맞춰 지속적인 모니터링과 개선 프로세스를 강화해야함
B37: ㄴ 1. 일자리의 질적 수준을 높이기 위해 마련된 근로자 친화적 고용정책이나 인사규정 등이 마련되어 있다 | E37: TRUE | O37: 0.83333333 | P37: =IF(E37=TRUE,O37,0) -> 0.83333333 | Q37: 근로자 권리 및 역량향상에 더 많은 노력이 필요함 | U37: 혁신노력 | V37: 혁신노력 | W37: 2단계 | X37: 29 | Y37: =O144 -> 3 | AB37: =VLOOKUP($Y37,$AC$139:$AD$143,2,0) -> 내외부 혁신 노력으로 조직의 성장과 경쟁력 확보를 하도록 해야함
B38: ㄴ 2. 근로자 보건 및 안전을 위해 정기적인 보건〮위생 등 안전교육을 실시하고 있다 | E38: TRUE | O38: 0.83333333 | P38: =IF(E38=TRUE,O38,0) -> 0.83333333 | Q38: 근로자 권리 및 역량향상에 대한 노력을 하고 있음 | S38: 3관점, 5개범주 | U38: =COUNTA(U12:U37) -> 15 | V38: =COUNTA(V12:V37) -> 26 | Y38: =SUM(Y12:Y37)/125*100 -> 66.6
B39: ㄴ 3. 근로자 보건 및 안전을 위해 유상진료의 건강검진비를 지원하고 있다 | E39: TRUE | O39: 0.83333333 | P39: =IF(E39=TRUE,O39,0) -> 0.83333333 | Q39: 근로자 권리 및 역량향상에 대한 노력을 충분히 하고 있음
B40: ㄴ 4. 근로자의 역량강화를 위한 교육훈련비 지출 내용이 있다 | E40: FALSE | O40: 0.83333333 | P40: =IF(E40=TRUE,O40,0) -> 0
B41: ㄴ 5. 근로자 역량강화를 위한 사업영역과 관련된 교육을 받을 수 있는 환경을 제공한다 (ex. 내외부교육, 진학, 자격증취득, 도서구입비 등) | E41: FALSE | O41: 0.83333333 | P41: =IF(E41=TRUE,O41,0) -> 0 | T41: 그래프1 | U41: 요인 | V41: 해당점수 | W41: 1.7미만 | X41: 3.4미만 | Y41: 이상 | Z41: 요인
B42: ㄴ 6. 근로자 근로환경개선이나 추가고용을 위한 시설투자를 한 사례가 있다 (사업상 필요한 시설투자 제외) | E42: FALSE | O42: 0.83333333 | P42: =IF(E42=TRUE,O42,0) -> 0 | T42: 조직미션 | U42: 소셜미션 | V42: =AVERAGE(Y12:Y13) -> 3 | W42: =IF(V42<1.7,V42,"") | X42: =IF(AND(V42>=1.7,V42<3.4),V42,"") -> 3 | Y42: =IF(V42>=3.4,V42,"") | Z42: 소셜미션
...

Sheet 심화진단 보고서
B2: 입주기업 기초진단 결과보고서
B4: 기업명 | F4: =심화진단!E3 -> 협동조합 가나다라 | Q4: 자가진단일 | U4: =심화진단!E2 -> 45606 | AG4: 기업은 진단 결과를 확인하며 요청사항에 대해 의견
B6: 담당 | F6: =심화진단!E4 -> 대표 홍길동 | Q6: 진단일 | U6: <면담일 기입>
B8: =""&F4&" 기업을 심화진단한 결과 가장 취약한 영역은 "&심화진단!W70&"입니다" -> 협동조합 가나다라 기업을 심화진단한 결과 가장 취약한 영역은 사회적성과입니다
B9: ="세부적으로 살펴보면 상대적으로 "&심화진단!X70&" 요인이 낮습니다. 하지만 "&심화진단!X72&" 요인은 긍정적으로 높게 나타났습니다. 그리고 "&심화진단!AB10&" 확인하였습니다." -> 세부적으로 살펴보면 상대적으로 지역협력 요인이 낮습니다. 하지만 민주적 의사결정 구조 요인은 긍정적으로 높게 나타났습니다. 그리고 사업경험도 있고 동종업종 경험도 있음을 확인하였습니다.
R14: =VLOOKUP(심화진단!Y62,심화진단!P166:Q197,2,0) -> 사업활동 영역 강화가 필요합니다. 사회적 가치 창출을 위한 구체적 사업계획 수립과 실행방안 모색이 요구됩니다. 명확한 목표 설정과 성과 측정을 통해 지속적으로 개선해 나가야 합니다. 이를 위해 시장 조사 및 분석을 통해 고객의 요구와 사회적 문제를 파악하고, 이를 해결하기 위한 혁신적인 사업 모델을 개발해야 합니다. 또한, 사업 성과를 정기적으로 평가하여 필요한 조정을 통해 목표 달성을 촉진해야 합니다.
B27: [소셜미션· 사업계획수립] | AG27: 기업의 진단 결과를 확인하며 면담하여 담당자의 의견 서술
B28: =IFERROR(심화진단!AB12 &" "& 심화진단!AB13 &" "& 심화진단!AB15 &" "& 심화진단!AB14,"선택을 다시 확인하세요") -> 사회적문제 해결을 위한 시도의 결과를 분석하며 개선점을 도출하고 소셜미션을 구체적으로 수립하며 직원들과 정기적회의를 진행하며 관리해야함 정기적인 사업성과평가와 피드백을 통해 보완하여야함
B32: [기업의 사회적가치·사회적경제기업협력·지역협력 ]
B33: =IFERROR(심화진단!AB16 &" " &심화진단!AB17 & ". 외부로는 "& 심화진단!AB18 & ". 또한, " &심화진단!AB19 &" "&심화진단!AB20,"선택을 다시 확인하세요") -> 근로자 안전을 위한 지속적인 교육&훈련을 통해 안전 문화를 정착으로 근로자 권리 및 역량향상에 대한 노력을 하고 있음. 외부로는 지역 자원의 활용도 증대와 지역 사회와의 협력을 강화해야함. 또한, 사회적경제기업과 협력사업을 확대하며 지속가능한 관계를 구축하고 지역기업과의 거래를 우선하여 지역경제 활성화에 기여해야함
B40: [사회환원 ]
B41: =IFERROR(심화진단!AB21 &" "&심화진단!AB22,"선택을 다시 확인하세요") -> 사회적환원 비율을 높이고 계획을 수립하며 실행하고 지역사회 기부나 사회공헌사업에 대해 관심을 가질 필요가 있음
B44: [ 민주적 의사결정·고용·교육 ]
B45: =IFERROR(심화진단!AB23 &" " &심화진단!AB24 &". 그리고 "& 심화진단!AB25 &" 교육으로 "&심화진단!AB26,"선택을 다시 확인하세요") -> 근로자들이 회의결과에 대해 의견을 제시할 수 있는 기회를 제공하고 고용 계획 수립과 인력확보 방안 모색이 필요함. 그리고 근로자 근로조건은 우수하나 복리후생비, 성과급 등 임금체계에 대한 향상을 권장함 교육으로 대표자의 교육수료 내용을 구성원들과 공유하길 권장함
B51: [ 비즈니스모델 ]
B52: =IFERROR(심화진단!AB28 &" "& 심화진단!AB30 &" 경제적성과는 "&심화진단!AB31, "선택을 다시 확인하세요") -> 상품의 안정적인 공급망 유지 및 품질관리를 위해 노력하고, 시장을 세분화하고, 타켓 시장을 설정하여 상품 포지션을 찾는 마케팅 계획을 수립해야함 경제적성과는 고정매출로 우수한 경제적성과를 이루고 있음
B55: [ 성장잠재력·사업아이템· 시장분석 ]
B56: =IFERROR(심화진단!AB32 &" "& 심화진단!AB33 & " "& 심화진단!AB37,"선택을 다시 확인하세요") -> 혁신적인 프로젝트를 통해 새로운 시장 진입을 적극적으로 시도하고 경쟁사의 성공 사례를 벤치마킹하여 전략을 수립하고 내외부 혁신 노력으로 조직의 성장과 경쟁력 확보를 하도록 해야함
